# Исключения и обработка ошибок

Лекция от разработчика из MS про реализации обработку ошибок вообще: http://joeduffyblog.com/2016/02/07/the-error-model/

## Два вида ошибок:

1. Ошибки программирования: любой UB, нарушения инварианта (двоичный поиск, нарушение инварианта и тд.)
    * Лучше выявлять на стадии тестирования.
    * Обычно видны не сразу, а через какое-то время.
    * Можно пробовать проверять и детектировать (например, `vector::at` вместо `vector::operator[]`), но не
      задетектирует всё (потому что баги) и неясно, что делать после обнаружения
      (мало в чём можно быть уверенным).
    * Если случилось, то никаких гарантий, all bets are off. Баг в программе точно есть, причём неизвестный, могло
      упасть где угодно.
    * Что делать, если ошибка произошла -- непонятно. Обычно просто роняет программу.
2. "Ошибки окружения": некорректный ввод пользователя, файл не найден, оборвалось сетевое соединение....
    * Могут произойти независимо от программы.
    * Лучше обрабатывать.
    * Например, клиент Telegram должен быстро работать, даже если сервер внезапно отвалился. Переподключиться? Держать
      ещё одно соединение в запасе? Надо думать.
    * Не хватило прав доступа — может, наоборот, не сообщать пользователю, зато сообщить администратору.

Примеры:
Бывают пограничные ситуации в разных контекстах.

* На хороших контестах гарантируется, что ввод корректен.
* А что если кончился стэк/память/место на диске?
    * Место на диске: можно забить, можно почистить свой собственный кэш.
    * Память: а если при обработке потребуется ещё память?
    * Не удалась запись в файл: могут быть разные требования к чат-клиенту (который может всё скачать с сервера) и
      самому серверу (которому надо как-то восстанавливаться и централизованно сообщать "жёсткий диск сломался").
* Нарушен инвариант структуры — проблема. А вот если мы её перед этим считывали по сети, то, может, это попытка взлома и
  надо залогировать и пропустить запрос.

Про каждую ошибку в программе надо думать:

1. Что случится, когда произойдёт? (не "если")
2. Можно ли с ней сделать что-то разумное?

## Обработка ошибок

Почти всегда можно залогировать ошибку _для разработчика_.

1. Уронить процесс целиком. Самое безопасное при ошибках программирования. Хотя тоже может нарушить инварианты (
   например, файл не до конца записали). Можно ещё перед этим позвонить домой и отправить багрепорт. А потом немедленно
   упасть, даже если кажется, что всё хорошо.
1. Уронить кусок процесса. Только если не ошибка программирования (хотя в Java/Python с изоляцией получше). Например, мы
   сервер и порвалось соединение с клиентом.
1. Как-то обработать: например, попробовать другой адрес для подключения к серверу.
1. Сообщить пользователю и попросить что-нибудь сделать: "файл не найден, выберите другой".
    * Важно понимать, что пользователь далеко не всегда что-то может сделать. О каких ошибках и как сообщать
      пользователю — отдельный вопрос.

Проще и надёжнее всего уронить программу целиком.

Нет серебрянной пули для обработки ошибок: это такая же часть спецификации программы, над которой надо хорошо думать
заранее и отдельно реализовывать.

Например, `On Error Resume Next` писать не надо никогда.

## Обработка ошибок в C++

### Object state flag

```c++
std::ifstream f(filename);
std::cout << "Reading from " << filename << "\n";
// Easy to forget to check.
std::cout << "    is_open: " << f.is_open() << "\n";
for (;;) {
    // https://en.cppreference.com/w/cpp/io/ios_base/iostate
    // State, not result of operation
    std::cout << "    status: " << f.rdstate() << "; "
              << std::ios_base::badbit << " "  // irrecoverable error
              << std::ios_base::failbit << " "  // format/extract error
              << std::ios_base::eofbit << "\n";  // EOF reached
    if (!f) {
        break;
    }
    int x = -239;
    // Careful handling is actually required: https://en.cppreference.com/w/cpp/named_req/FormattedInputFunction
    f >> x;
    std::cout << "    x = " << x;
}
```

Здесь показан простой пример флага состояния: в `ifstream` мы просто после каждой операции можем проследить состояние:
получилось прочитать/сломалось ли все/конец файла.

Проблема: таких состояний довольно ограниченное состояние + это довольно легко забыть.

### Global Errno

Способ прямиком из C. В Си мы открывали файлы через `fopen`, которое возвращала указатель на файл. А ошибка хранилась
в `errno`. Формально -- это макрос: вызов функции/глобальная переменная, в которой хранятся все ошибки:

```c++
FILE *f = std::fopen(filename.c_str(), "r");
std::cout << "Reading from " << filename << "\n";
std::cout << "    f: " << f << ", errno: " << errno << " " << std::strerror(errno) << "\n";  // POSIX (not C/C++) requires that errno macro is set.
// Problem: have to check immediately after each function. Does not propagate up.
if (f == nullptr) {
    return;
}
for (;;) {
    int x = -239;
    int read = fscanf(f, "%d", &x);  // Still easy to forget to check.
    std::cout << "    x = " << x << ", read = " << read << ", errno = " << errno << " " << std::strerror(errno) << "\n";
    if (read != 1) {
        break;
    }
}
```

### Return value

Еще одна конвенция: функция возвращает `int` -- код ошибки (а то, что обычно возвращает передаётся по ссылке). Например:

```c++
sqlite3 *db;
if (int err = sqlite3_open("does-not-exist/some-db.sqlite3", &db); err != SQLITE_OK) {  // Still easy to forget to check, but syntax is ugly.
    std::cout << "err = " << err << " " << sqlite3_errstr(err) << "\n";
    if (err == SQLITE_CANTOPEN) {
        std::cout << "Unable to open DB file\n";
    }
    return 1;
}
sqlite3_close(db);
```

### Either

Модный способ обработки ошибки: любая функция возвращает либо `Ok(res)`, либо `Err(res)`. Поэтому нам всегда придется
обрабатывать ошибки. Пример (внимание, Rust):

```rust
// https://doc.rust-lang.org/book/ch09-02-recoverable-errors-with-result.html
use std::fs::File;
use std::io::Read;

fn main() {
    let mut f = match File::open("hello.txt") {  // We have to check.
        Ok(file) => file,
        Err(error) => {
            println!("Problem opening the file: {:?}", error);
            return
        },
    };
    let mut s = String::new();
    match f.read_to_string(&mut s) {
        Ok(_) => println!("File read: {:?}", s),
        Err(e) => {
            println!("Problem reading the file: {:?}", e);
            return
        }
    }
}
```

Обрабатывать все ошибки может быть утомительно. Поэтому обычно вводят свой синтаксис для "пропуска" ошибки:

```rust
// https://doc.rust-lang.org/book/ch09-02-recoverable-errors-with-result.html
use std::fs::File;
use std::io::Error;
use std::io::Read;

fn main() -> Result<(), Error> {
    let mut f = File::open("hello.txt")?;  // '?' is a shortcut for "if failure, return Err()".
    let mut s = String::new();
    f.read_to_string(&mut s)?;
    println!("File read: {:?}", s);
    Ok(())
}
```

## Три стратегии обработки исключений

### Пора возвращаться домой

Посмотрим простой пример "обработки" ошибки:

```c++
std::vector<int> read_vector(const std::string &filename) {
    std::ifstream f(filename);
    assert(f);  // Why no handling?
    int n;
    f >> n;
    assert(f);
    std::vector<int> vec(n);
    for (int &v : vec) {
        f >> v;
        assert(f);
    }
    return vec;
}
```

Почему же тут нет обработки ошибки? Потому что в `Release` моде ассерты просто вырезаются.

### Обрабатываем in-place

```c++
std::vector<int> read_vector(const std::string &filename) {
    std::ifstream f(filename);
    if (!f) {
        std::cerr << "Unable to open file\n";
        std::exit(1);
    }

    int n;
    if (!(f >> n)) {
        std::cerr << "Unable to read length of a vector\n";
        std::exit(1);
    }

    std::vector<int> vec(n);
    for (int &v : vec) {
        if (!(f >> v)) {
            std::cerr << "Unable to read number\n";
            std::exit(1);
        }
    }
    return vec;
}
```

Обработали ошибку как-то.

### Передаем ошибку наверх

```c++
enum class read_vector_error { OK, CANNOT_OPEN, CANNOT_READ_LENGTH, CANNOT_READ_NUMBER };

read_vector_error read_vector(const std::string &filename, std::vector<int> &result) {
    std::ifstream f(filename);
    if (!f) {
        return read_vector_error::CANNOT_OPEN;
    }

    int n;
    if (!(f >> n)) {
        return read_vector_error::CANNOT_READ_LENGTH;
    }

    std::vector<int> vec(n);
    for (int &v : vec) {
        if (!(f >> v)) {
            return read_vector_error::CANNOT_READ_NUMBER;
        }
    }
    result = std::move(vec);
    return read_vector_error::OK;
}
```

Такой способ уже используется, но основная проблема: мы пока не знаем в какой переменной произошла ошибка.

## Исключения!

Все что использовались выше сделано без использования механизмов языка. Теперь посмотрим как сделать то же самое, но с
использованием C++:

```c++
struct invalid_vector_format {};

std::vector<int> readVector() {
    int n;
    if (!(std::cin >> n)) {
        throw invalid_vector_format();
    }
    std::vector<int> result(n); // может кинуть исключение.
    for (int i = 0; i < n; i++) {
        if (!(std::cin >> result[i])) {
            throw invalid_vector_format(); // кинул исключение, знаем, что кто-нибудь поймает.
        }
    }
    return result;
}

void writeAnswer(const std::vector<int> &vec) {
    for (std::size_t i = 0; i < vec.size(); i++) {
        if (i) std::cout << " ";
        std::cout << vec[i];
    }
    std::cout << "\n";
}

void solve() {
    std::vector<int> a = readVector();
    std::vector<int> b = readVector();  // исключение пролетело насквозь
    
    // Тут какие-то вычисления
    std::vector<int> answer = a;
    answer.insert(answer.end(), b.begin(), b.end());

    writeAnswer(answer);
}

int main() {
    try {
        solve(); // исключение пролетело насквозь
    } catch (const invalid_vector_format &err) {
        std::cout << "Invalid vector format\n";
    }
}
```

Появилось новое ключевое слово `throw`: можно кидать любой объект. Кидаем какой-то объект, который летит наверх по
стеку, аварийно завершая все функции ровно до того момента, пока мы его не поймаем.

Чтобы поймать если структура `try { ... } catch (const T& err) { ... }`.

Основные проблемы, которые остались: мы пока не знаем, где мы были (stacktrace), оно СУПЕР медленное.

Что происходит под капотом? Черная магия! Потому что исключению надо пропихивать наверх сквозь единиц трансляции,
библиотеки и остальной мусор.

Конечно же, никто не запрещает делать много `catch`'ей. Они просто выполняются сверху вниз:

### Много `catch`'ей

```c++
try {
    throw err1(); // only one throw per time
    throw err2();
    std::vector v(-1); // -1 -> Too big -> bad_alloc
} catch (const err1 &) {
    std::cout << "1\n";
} catch (const err2 &) {
    std::cout << "2\n";
} catch (...) { // Exceptions only. Not UB, not asserts
    std::cout << "3\n";
}
```

### Наследование исключений

В `catch` не может происходить приведений типов, но наследование работает как обычно: слайсинг, basecast работает:

```c++
// А где пример?
```

### Ошибки в `catch`...

Посмотрим на комплексный прмиер:

```c++
#include <iostream>

struct err1 {};
struct err2 {};

void bar() {
    try {
        try {
            std::cout << "3\n";
            throw err1();
            std::cout << "x3\n";
        } catch (const err1 &e) {
            std::cout << "4\n";
            throw err2();
            std::cout << "x4\n";
        } catch (const err2 &e) {
            std::cout << "x5\n";
        }
    } catch (int e) {
        std::cout << "caught int???\n";
//    } catch (const err2 &e) {
//        std::cout << "caught err2!\n";
//        throw e;
    }
    std::cout << "bar end\n";
}

void foo() {
    try {
        try {
            std::cout << "2\n";
            bar();  // std::cout << "3\n4\n"; throw err2();
            std::cout << "x2\n";
        } catch (const err1 &e) {
            std::cout << "z\n";
        }
        std::cout << "x21\n";
    } catch (int e) {
        std::cout << "x22\n";
    }
    std::cout << "foo end\n";
}

int main() {
    try {
        std::cout << "1\n";
        foo();
        std::cout << "xxx\n";
    } catch (const err2 &) {
        std::cout << "5\n";
    }
    std::cout << "main continues\n";
}
```

Что произойдет: сначала кинется `err1`, в `bar` оно поймается во внутреннем `try`, в блоке `catch` кинется `err2`,
который полетит наверх... вплоть до `main`. Выведется: `1 2 3 4 5`

При этом, если раскомментировать часть в `bar`, то у нас будет выкидываться наверх это же исключение.
Выведется `1 2 3 4 caught err2! 5`.

### Заб(ы/и)ли на обработку

Пока мы летим с исключением наверх мы "раскручиваем стек", то есть удаляем все лишнее, пока не найдем нужный `catch`.

```c++
#include <iostream>

struct err1 {};
struct err2 {};

struct WithDestructor {
    int key;
    WithDestructor(int key_) : key(key_) {}
    ~WithDestructor() {
        std::cout << "Destructed " << key << "\n";
    }
};

void bar() {
    WithDestructor wd31(31);  // Implementation-defined раскрутка.
    try {
        WithDestructor wd40(40);
        std::cout << "3\n";
        throw err1();
        std::cout << "x3\n";
    } catch (const err1 &e) {
        std::cout << "4\n";
        throw err2();
        std::cout << "x4\n";
    }
    std::cout << "bar end\n";
}

void foo() {
    WithDestructor wd20(20);  // Implementation-defined раскрутка.
    try {
        WithDestructor wd30(30);  // Implementation-defined раскрутка.
        std::cout << "2\n";
        bar();
        std::cout << "x2\n";
    } catch (const err1 &e) {
        std::cout << "z\n";
    }
    std::cout << "foo end\n";
}

int main() {
    std::cout << "1\n";
    {
        WithDestructor wd10(10);
    }
    //try {
        foo();
    //} catch (...) {
    //    throw;  // "Перебрось текущее исключение".
    //}
    std::cout << "main end\n";
}
```

Но при этом, если ошибка вылетает из `main`, то есть мы её не обработали, то раскрутка `implementation defined`, а
значит, деструкторы могут не вызваться.

## Стандартные исключения

Они все наследуются от `std::exception`. Он умеет копироваться + у него есть метод `what`(шта?).

Например: все, что выделяет память может кидать `std::bad_alloc`. `stoi` может кидать `std::invalid_argument`.

Все это ловится при помощи `std::exception`.

Обычно все кастомные исключения наследуются от `std::exception` (на самом деле от `std::logic_error`
или `std::runtime_error`):

```c++
struct my_exception : std::exception {
    const char* what() const noexcept override {
        return "my_exception";
    }
};
```

- `std::logic_error` -- про нарушение контрактов/инвариантов. То есть то, что можно починить во время программирования.
- `std::runtime_error` -- про нарушение чего-то во время выполнения программы. 